Workbook

Sheet CATALOGO_MOTOS
C2: LISTA DE PRECIOS | I2: MANO DE OBRA GRATIS EN 2° SERVICIO
B4: Clave | C4: Modelo | D4: Precio Lista | E4: Precio Contado | G4: 3 Meses
B5: SCOOTER
A6: 1 | C6: X MAX TECH MAX | D6: 178947 | E6: 169999 | F6: =D6*3% -> 5368.41 | G6: =D6-F6 -> 173578.59 | J6: =D6*5% -> 8947.35 | K6: =D6-J6 -> 169999.65 | L6: MOTONETA X MAX TECH MAX (2026)
F7: =D7*3% -> 0 | G7: =D7-F7 -> 0 | J7: =D7*5% -> 0 | K7: =D7-J7 -> 0
A8: 2 | B8: CZD300BS | C8: X MAX (2025) | D8: 170526 | E8: 161999 | F8: =D8*3% -> 5115.78 | G8: =D8-F8 -> 165410.22 | J8: =D8*5% -> 8526.3 | K8: =D8-J8 -> 161999.7 | L8: MOTONETA X MAX (2025)
A10: 3 | B10: CZD300BT | C10: X MAX (2026) | D10: 172631 | E10: 163999 | F10: =D10*3% -> 5178.93 | G10: =D10-F10 -> 167452.07 | J10: =D10*5% -> 8631.55 | K10: =D10-J10 -> 163999.45 | L10: MOTONETA X MAX (2026)
F11: =D11*3% -> 0 | G11: =D11-F11 -> 0 | J11: =D11*5% -> 0 | K11: =D11-J11 -> 0
A12: 4 | B12: LCX125BS | C12: FASCINO | D12: 49473 | E12: 46999 | F12: =D12*3% -> 1484.19 | G12: =D12-F12 -> 47988.81 | J12: =D12*5% -> 2473.65 | K12: =D12-J12 -> 46999.35 | L12: MOTONETA FASCINO (2025) | M12: CON BONO 2,000.00 | O12: 44999
F13: =D13*3% -> 0 | G13: =D13-F13 -> 0 | J13: =D13*5% -> 0 | K13: =D13-J13 -> 0
A14: 5 | B14: XP560DZ4 | C14: T-MAX (2025) | D14: 385262 | E14: 365999 | F14: =D14*3% -> 11557.86 | G14: =D14-F14 -> 373704.14 | J14: =D14*5% -> 19263.1 | K14: =D14-J14 -> 365998.9 | L14: MOTONETA T-MAX (2025)
A16: 6 | B16: XP560 | C16: T-MAX (2026) | D16: 387368 | E16: 367999 | F16: =D16*3% -> 11621.04 | G16: =D16-F16 -> 375746.96 | J16: =D16*5% -> 19368.4 | K16: =D16-J16 -> 367999.6 | L16: MOTONETA T-MAX (2026)
A18: 7 | B18: GPD155BS | C18: N-MAX (2025) | D18: 104736 | E18: 99499 | F18: =D18*3% -> 3142.08 | G18: =D18-F18 -> 101593.92 | J18: =D18*5% -> 5236.8 | K18: =D18-J18 -> 99499.2 | L18: MOTONETA N-MAX (2025)
F19: =D19*3% -> 0 | G19: =D19-F19 -> 0 | J19: =D19*5% -> 0 | K19: =D19-J19 -> 0
A20: 8 | B20: GPD155Bt | C20: N-MAX (2026) | D20: 105262 | E20: 99999 | F20: =D20*3% -> 3157.86 | G20: =D20-F20 -> 102104.14 | J20: =D20*5% -> 5263.1 | K20: =D20-J20 -> 99998.9 | L20: MOTONETA N-MAX (2026)
F21: =D21*3% -> 0 | G21: =D21-F21 -> 0 | J21: =D21*5% -> 0 | K21: =D21-J21 -> 0
A22: 9 | B22: LCG125BS | C22: RAY ZR 125 (2025) | D22: 57367 | E22: 54499 | F22: =D22*3% -> 1721.01 | G22: =D22-F22 -> 55645.99 | J22: =D22*5% -> 2868.35 | K22: =D22-J22 -> 54498.65 | L22: MOTONETA RAY ZR 125 (2025)
F23: =D23*3% -> 0 | G23: =D23-F23 -> 0 | J23: =D23*5% -> 0 | K23: =D23-J23 -> 0
A24: 10 | B24: LCG125BT | C24: RAY ZR 125 (2026) | D24: 57894 | E24: 54999 | F24: =D24*3% -> 1736.82 | G24: =D24-F24 -> 56157.18 | J24: =D24*5% -> 2894.7 | K24: =D24-J24 -> 54999.3 | L24: MOTONETA RAY ZR 125 (2026)
F25: =D25*3% -> 0 | G25: =D25-F25 -> 0 | J25: =D25*5% -> 0 | K25: =D25-J25 -> 0
A26: 11 | B26: XC115BNS | C26: CYGNUS RAY ZR 2025 | D26: 40525 | E26: 38499 | F26: =D26*3% -> 1215.75 | G26: =D26-F26 -> 39309.25 | J26: =D26*5% -> 2026.25 | K26: =D26-J26 -> 38498.75 | L26: MOTONETA CYGNUS RAY ZR (2025)
A28: 12 | B28: XC115BNT | C28: CYGNUS RAY ZR (2026) | D28: 41052 | E28: 38999 | F28: =D28*3% -> 1231.56 | G28: =D28-F28 -> 39820.44 | J28: =D28*5% -> 2052.6 | K28: =D28-J28 -> 38999.4 | L28: MOTONETA CYGNUS RAY ZR (2026) | M28: CON BONO 1,000.00 | O28: 37999
B29: TRABAJO | F29: =D29*3% -> 0 | G29: =D29-F29 -> 0 | J29: =D29*5% -> 0 | K29: =D29-J29 -> 0
A30: 13 | B30: YB125ZR | C30: YBR 125ZR (2026) | D30: 46315 | E30: 43999 | F30: =D30*3% -> 1389.45 | G30: =D30-F30 -> 44925.55 | J30: =D30*5% -> 2315.75 | K30: =D30-J30 -> 43999.25 | L30: MOTOCICLETA YBR 125ZR (2026)
F31: =D31*3% -> 0 | G31: =D31-F31 -> 0 | H31: MANO DE OBRA GRATIS EN 2° SERVICIO | I31: MANO DE OBRA GRATIS EN 2° SERVICIO | J31: =D31*5% -> 0 | K31: =D31-J31 -> 0
A32: 14 | B32: YB125BR | C32: YB 125 (2026) | D32: 39999 | E32: 37999 | F32: =D32*3% -> 1199.97 | G32: =D32-F32 -> 38799.03 | I32: 1AÑO SERVICIO o 5 SERVICIOS | J32: =D32*5% -> 1999.95 | K32: =D32-J32 -> 37999.05 | L32: MOTOCICLETA YB 125 (2026)
H33: MANO DE OBRA GRATIS EN 2° SERVICIO | I33: MANO DE OBRA GRATIS EN 2° SERVICIO
A34: 15 | B34: YBR125CBS | C34: YBR 125C EXPRESS (2025) | D34: 41052 | E34: 38999 | F34: =D34*3% -> 1231.56 | G34: =D34-F34 -> 39820.44 | J34: =D34*5% -> 2052.6 | K34: =D34-J34 -> 38999.4 | L34: MOTOCICLETA YBR 125C EXPRESS (2025)
H35: MANO DE OBRA GRATIS EN 2° SERVICIO | I35: MANO DE OBRA GRATIS EN 2° SERVICIO
A36: 16 | B36: YBR125CBS | C36: YBR 125C EXPRESS (2026) | D36: 41052 | E36: 38999 | F36: =D36*3% -> 1231.56 | G36: =D36-F36 -> 39820.44 | I36: 1AÑO SERVICIO o 5 SERVICIOS | J36: =D36*5% -> 2052.6 | K36: =D36-J36 -> 38999.4 | L36: MOTOCICLETA YBR 125C EXPRESS (2026) | M36: CON BONO 2,000.00 | O36: 36999
H37: MANO DE OBRA GRATIS EN 2° SERVICIO | I37: MANO DE OBRA GRATIS EN 2° SERVICIO
A38: 17 | B38: T115CBT | C38: CRYPTON 115 FI (2026) | D38: 37894 | E38: 35999 | F38: =D38*3% -> 1136.82 | G38: =D38-F38 -> 36757.18 | J38: =D38*5% -> 1894.7 | K38: =D38-J38 -> 35999.3 | L38: MOTOCICLETA CRYPTON 115 FI (2026)
B39: STREET | F39: =D39*3% -> 0 | G39: =D39-F39 -> 0 | J39: =D39*5% -> 0 | K39: =D39-J39 -> 0
A40: 18 | B40: FZSV2BT | C40: FZ S VERSION 2.0 2026 | D40: 59999 | E40: 56999 | F40: =D40*3% -> 1799.97 | G40: =D40-F40 -> 58199.03 | J40: =D40*5% -> 2999.95 | K40: =D40-J40 -> 56999.05 | L40: MOTOCICLETA FZ S VERSION 2.0 2026 | M40: CON BONO | O40: 54999
A42: 19 | B42: FZSBT | C42: FZ S VERSION 3.0 2026 | D42: 66315 | E42: 62999 | F42: =D42*3% -> 1989.45 | G42: =D42-F42 -> 64325.55 | J42: =D42*5% -> 3315.75 | K42: =D42-J42 -> 62999.25 | L42: MOTOCICLETA FZ VERSION 3.0 2026
A44: 20 | B44: FZSBR | C44: FZ S V 4.0 ABS (2025) | D44: 70525 | E44: 66999 | F44: =D44*3% -> 2115.75 | G44: =D44-F44 -> 68409.25 | J44: =D44*5% -> 3526.25 | K44: =D44-J44 -> 66998.75 | L44: MOTOCICLETA FZ S V 4.0 ABS (2025)
A46: 21 | B46: FZSBR | C46: FZ S V 4.0 ABS (2026) | D46: 71578 | E46: 67999 | F46: =D46*3% -> 2147.34 | G46: =D46-F46 -> 69430.66 | J46: =D46*5% -> 3578.9 | K46: =D46-J46 -> 67999.1 | L46: MOTOCICLETA FZ S V 4.0 ABS (2026)
A48: 22 | B48: FZ25BS6 | C48: FZ 25 ABS NUEVA (2025) | D48: 93683 | E48: 88999 | F48: =D48*3% -> 2810.49 | G48: =D48-F48 -> 90872.51 | J48: =D48*5% -> 4684.15 | K48: =D48-J48 -> 88998.85 | L48: MOTOCICLETA FZ 25 NUEVA (2025)
A50: 23 | B50: FZ25BS6 | C50: FZ 25 ABS NUEVA (2026 | D50: 94736 | E50: 89999 | F50: =D50*3% -> 2842.08 | G50: =D50-F50 -> 91893.92 | J50: =D50*5% -> 4736.8 | K50: =D50-J50 -> 89999.2 | L50: MOTOCICLETA FZ 25 NUEVA (2026)
A52: 24 | B52: FZ25BS | C52: FZ 25 ABS (2025) | D52: 91578 | E52: 86999 | F52: =D52*3% -> 2747.34 | G52: =D52-F52 -> 88830.66 | J52: =D52*5% -> 4578.9 | K52: =D52-J52 -> 86999.1 | L52: MOTOCICLETA FZ 25 (2025)
...

Sheet CREDITO2026
C4: Distribuidor Autorizado
C6: De Los Ángeles Motor´s
C7: Av. Reforma Sur #703 Col.Guadalupe Hidalgo Tehuacán, Pue.
C11: COTIZACION MOTOCICLETA YAMAHA
C14: CODIGO | D14: DESCRIPCION | I14: IMPORTE
C16: 14 | D16: =VLOOKUP(C16,CATALOGO_MOTOS!A6:L245,12) -> MOTOCICLETA YB 125 (2026) | I16: =VLOOKUP(C16,CATALOGO_MOTOS!A6:D245,4) -> 39999 | J16: =VLOOKUP(C16,CATALOGO_MOTOS!A6:M245,13) -> 0
C18: 5 | D18: % Descuento Por Pago de Contado | I18: =VLOOKUP(C16,CATALOGO_MOTOS!A6:E245,5) -> 37999 | J18: =VLOOKUP(C16,CATALOGO_MOTOS!A6:O245,15) -> 0
C20: 3 | D20: % Descuento Por Pago a 3 meses | I20: =VLOOKUP(C16,CATALOGO_MOTOS!A6:G245,7) -> 38799.03
I22: =(I16-H23) -> 23999.4
D23: 0.4 | E23: % de Enganche | H23: =I16*D23 -> 15999.6
D25: 3 | E25: Mensualidades | H25: =(I20-H23)/3 -> 7599.81 | I25: =H23+(H25*D25) -> 38799.03
D27: 6 | E27: Mensulaidades | H27: =(I22*12%+I22)/6 -> 4479.888 | I27: =H23+(H27*D27) -> 42878.928 | J27: =I27-I16 -> 2879.928
D29: 8 | E29: Mensualidades | H29: =(I22*16%+I22)/8 -> 3479.913 | I29: =H23+(H29*D29) -> 43838.904 | J29: =I29-I16 -> 3839.904
D33: PROMOCION DURANTE EL MES:
D34: PROMOCION DEL MES : | H34: =VLOOKUP(C16,CATALOGO_MOTOS!A6:I245,9) -> 1AÑO SERVICIO o 5 SERVICIOS
D37: REQUISITOS PARA CREDITO:
C38: 1. Credencial INE original vigente.
C39: 2. CURP.
C40: 3. Número de telefono | J40: (SE QUEDAN COPIAS)
C41: 4. Correo Electronico.
C42: 5. Comprobante de domicilio original no mayor a tres meses
C43: 6. Garantía que cubra el total del crédito solicitado, más un 30% adicional como respaldo.
C44: a) Escritura de propiedad con predial pagado y carta libre de gravamen.
C45: b) Factura de automovil o motocicleta endosada junto con tarjeta de circulación vigente
C48: Requisitos para métodos fiscales (si el cliente solicita factura para persona física o moral)
C49: • Alta de hacienda, RFC, hoja de situacion fiscal o formato 32-D
C50: • Acta constitutiva o nombramiento de representante legal
C51: • Constancia de situacion fiscal
C52: • 1 Estado de cuenta bancarios
D55: ATENDIDO POR: | G55: ANA MARIA CEPEDA BARROSO
D57: FECHA DE EMISION: | G57: =TEXT(TODAY(),"d \d\e mmmm \d\e aaaa") -> 7 de agosto de 2026
C60: En la compra de tu motocicleta, recibe un bono de $500.00 o
C61: un segundo servicio gratuito (solo mano de obra, no incluye insumos)
C62: Consulta la promoción que aplica este mes.
F64: www.yamaha-motor.com.mx
C67: N O T A S :
C68: * Incluye el 2% de interes Mensual *
C69: En caso de que el solicitante no cuente con una garantia, este debe contar con aval
C70: El Aval debe cumplir con los requisitos para credito (1 al 6).
C71: Facturas en garantía, incluida la de la moto, deben entregarse endosadas (firmadas al reverso). | L71: ANA MARIA CEPEDA BARROSO | M71: Casco de regalo
...
